const catchAsync = require('./../utils/catchAsync');
const AppError = require('./../utils/appError');

exports.deleteOne = (Model) =>
  catchAsync(async (req, res, next) => {
    const doc = await Model.findByIdAndDelete(req.params.id);
    if (!doc) {
      return next(new AppError('no document find with this id', 404));
    }
    res.status(204).json({
      status: 'success',
      message: 'document deleted successfully',
      data: null,
    });
  });

exports.createOne = (Model) =>
  catchAsync(async (req, res, next) => {
    const doc = await Model.create(req.body);
    res.status(201).json({
      status: 'success',
      data: doc,
    });
  });

exports.updateOne = (Model) =>
  catchAsync(async (req, res, next) => {
    const doc = await Model.findByIdAndUpdate(req.params.id, req.body, {
      new: true,
      runValidators: true,
    });
    if (!doc) {
      return next(new AppError('no document find with this id', 404));
    }
    res.status(200).json({
      status: 'success',
      data: doc ,
    });
  });